<?xml version="1.0" ?>
<!-- =================================================================================== -->
<!-- |    This document was autogenerated by xacro from ur3e_egh80.urdf.xacro          | -->
<!-- |    EDITING THIS FILE BY HAND IS NOT RECOMMENDED                                 | -->
<!-- =================================================================================== -->
<robot name="ur3e_egh80">
  <gazebo>
    <plugin filename="libgazebo_ros_control.so" name="ros_control">
      <!--robotNamespace>/</robotNamespace-->
      <!--robotSimType>gazebo_ros_control/DefaultRobotHWSim</robotSimType-->
    </plugin>
    <!--
    <plugin name="gazebo_ros_power_monitor_controller" filename="libgazebo_ros_power_monitor.so">
      <alwaysOn>true</alwaysOn>
      <updateRate>1.0</updateRate>
      <timeout>5</timeout>
      <powerStateTopic>power_state</powerStateTopic>
      <powerStateRate>10.0</powerStateRate>
      <fullChargeCapacity>87.78</fullChargeCapacity>     
      <dischargeRate>-474</dischargeRate>
      <chargeRate>525</chargeRate>
      <dischargeVoltage>15.52</dischargeVoltage>
      <chargeVoltage>16.41</chargeVoltage>
    </plugin>
-->
  </gazebo>
  <!-- measured from model "0.027"-->
  <!-- measured from model "0.027"-->
  <!--valores obtidos do Onshape, podem estar incorretos-->
  <!--xacro:property name="shoulder_height" value="0.094950" /-->
  <!--xacro:property name="upper_arm_length" value="0.243550" /-->
  <!--xacro:property name="forearm_length" value="0.2132" /-->
  <!--xacro:property name="wrist_1_length" value="0.01595" /-->
  <!--xacro:property name="wrist_2_length" value="0.08535" /-->
  <!--xacro:property name="wrist_3_length" value="0.0921" /-->
  <!--valores obtidos do Onshape, podem estar incorretos-->
  <!--<xacro:property name="shoulder_height" value="0.094950" /> -->
  <!--<xacro:property name="shoulder_offset" value="0.13585" /> -->
  <!-- shoulder_offset - elbow_offset + wrist_1_length = 0.10915 -->
  <!--<xacro:property name="upper_arm_length" value="0.42500" /> -->
  <!--<xacro:property name="elbow_offset" value="0.1197" /> -->
  <!-- CAD measured -->
  <!--<xacro:property name="forearm_length" value="0.39225" /> -->
  <!--<xacro:property name="wrist_1_length" value="0.093" />  -->
  <!-- CAD measured -->
  <!--<xacro:property name="wrist_2_length" value="0.09465" /> -->
  <!-- In CAD this distance is 0.930, but in the spec it is 0.09465 -->
  <!--<xacro:property name="wrist_3_length" value="0.0823" />-->
  <!-- manually measured -->
  <!--base_link-->
  <link name="base_link">
    <visual>
      <geometry>
        <mesh filename="package://robot_description/meshes/ur3e/visual/base.dae"/>
      </geometry>
      <material name="LightGrey">
        <color rgba="0.7 0.7 0.7 1.0"/>
      </material>
    </visual>
    <collision>
      <geometry>
        <mesh filename="package://robot_description/meshes/ur3e/collision/base.stl"/>
      </geometry>
    </collision>
    <inertial>
      <mass value="2.0"/>
      <origin rpy="0 0 0" xyz="0.0 0.0 0.0"/>
      <inertia ixx="0.0030531654454" ixy="0.0" ixz="0.0" iyy="0.0030531654454" iyz="0.0" izz="0.005625"/>
    </inertial>
  </link>
  <joint name="shoulder_pan_joint" type="revolute">
    <parent link="base_link"/>
    <child link="shoulder_link"/>
    <origin rpy="0.0 0.0 0.0" xyz="0.0 0.0 0.152"/>
    <axis xyz="0 0 1"/>
    <limit effort="56.0" lower="-3.141592653589793" upper="3.141592653589793" velocity="3.15"/>
    <dynamics damping="0.0" friction="0.0"/>
  </joint>
  <link name="shoulder_link">
    <visual>
      <geometry>
        <mesh filename="package://robot_description/meshes/ur3e/visual/shoulder.dae"/>
      </geometry>
      <material name="LightGrey">
        <color rgba="0.7 0.7 0.7 1.0"/>
      </material>
    </visual>
    <collision>
      <geometry>
        <mesh filename="package://robot_description/meshes/ur3e/collision/shoulder.stl"/>
      </geometry>
    </collision>
    <inertial>
      <mass value="3.7"/>
      <origin rpy="0 0 0" xyz="0.0 0.0 0.0"/>
      <inertia ixx="0.010267495893" ixy="0.0" ixz="0.0" iyy="0.010267495893" iyz="0.0" izz="0.00666"/>
    </inertial>
  </link>
  <joint name="shoulder_lift_joint" type="revolute">
    <parent link="shoulder_link"/>
    <child link="upper_arm_link"/>
    <origin rpy="0.0 1.5707963267948966 0.0" xyz="0.0 0.12 0.0"/>
    <!--<origin xyz="0.0 -0.06260 0.05690" rpy="${pi / 2.0} 0.0  0.0" />-->
    <axis xyz="0 1 0"/>
    <limit effort="56.0" lower="-3.141592653589793" upper="3.141592653589793" velocity="1.57079"/>
    <dynamics damping="0.0" friction="0.0"/>
  </joint>
  <link name="upper_arm_link">
    <visual>
      <geometry>
        <mesh filename="package://robot_description/meshes/ur3e/visual/upperarm.dae"/>
      </geometry>
      <material name="LightGrey">
        <color rgba="0.7 0.7 0.7 1.0"/>
      </material>
    </visual>
    <collision>
      <geometry>
        <mesh filename="package://robot_description/meshes/ur3e/collision/upperarm.stl"/>
      </geometry>
    </collision>
    <inertial>
      <mass value="3.4445"/>
      <origin rpy="0 0 0" xyz="0.0 0.0 0.28"/>
      <inertia ixx="0.022165039346584883" ixy="0.0" ixz="0.0" iyy="0.022165039346584883" iyz="0.0" izz="0.00968765625"/>
    </inertial>
  </link>
  <joint name="elbow_joint" type="revolute">
    <parent link="upper_arm_link"/>
    <child link="forearm_link"/>
    <origin rpy="0.0 0.0 0.0" xyz="0.0 -0.093 0.24355"/>
    <!--<origin xyz="0.0 0.243550 -0.010541" rpy="0.0 ${pi / 2.0} 0.0"/>-->
    <axis xyz="0 1 0"/>
    <limit effort="28.0" lower="-3.141592653589793" upper="3.141592653589793" velocity="1.57079"/>
    <dynamics damping="0.0" friction="0.0"/>
  </joint>
  <link name="forearm_link">
    <visual>
      <geometry>
        <mesh filename="package://robot_description/meshes/ur3e/visual/forearm.dae"/>
      </geometry>
      <material name="LightGrey">
        <color rgba="0.7 0.7 0.7 1.0"/>
      </material>
    </visual>
    <collision>
      <geometry>
        <mesh filename="package://robot_description/meshes/ur3e/collision/forearm.stl"/>
      </geometry>
    </collision>
    <inertial>
      <mass value="1.437"/>
      <origin rpy="0 0 0" xyz="0.0 0.0 0.25"/>
      <inertia ixx="0.0074639235044294035" ixy="0.0" ixz="0.0" iyy="0.0074639235044294035" iyz="0.0" izz="0.0040415625"/>
    </inertial>
  </link>
  <joint name="wrist_1_joint" type="revolute">
    <parent link="forearm_link"/>
    <child link="wrist_1_link"/>
    <origin rpy="0.0 1.5707963267948966 0.0" xyz="0.0 0.0 0.2132"/>
    <axis xyz="0 1 0"/>
    <limit effort="12.0" lower="-3.141592653589793" upper="3.141592653589793" velocity="3.1415"/>
    <dynamics damping="0.0" friction="0.0"/>
  </joint>
  <link name="wrist_1_link">
    <visual>
      <geometry>
        <mesh filename="package://robot_description/meshes/ur3e/visual/wrist1.dae"/>
      </geometry>
      <material name="LightGrey">
        <color rgba="0.7 0.7 0.7 1.0"/>
      </material>
    </visual>
    <collision>
      <geometry>
        <mesh filename="package://robot_description/meshes/ur3e/collision/wrist1.stl"/>
      </geometry>
    </collision>
    <inertial>
      <mass value="0.871"/>
      <origin rpy="0 0 0" xyz="0.0 0.0 0.0"/>
      <inertia ixx="0.0022700428419824997" ixy="0.0" ixz="0.0" iyy="0.0022700428419824997" iyz="0.0" izz="0.0024496874999999996"/>
    </inertial>
  </link>
  <joint name="wrist_2_joint" type="revolute">
    <parent link="wrist_1_link"/>
    <child link="wrist_2_link"/>
    <origin rpy="0.0 0.0 0.0" xyz="0.0 0.10405 0.0"/>
    <axis xyz="0 0 1"/>
    <limit effort="12.0" lower="-3.141592653589793" upper="3.141592653589793" velocity="3.1415"/>
    <dynamics damping="0.0" friction="0.0"/>
  </joint>
  <link name="wrist_2_link">
    <visual>
      <geometry>
        <mesh filename="package://robot_description/meshes/ur3e/visual/wrist2.dae"/>
      </geometry>
      <material name="LightGrey">
        <color rgba="0.7 0.7 0.7 1.0"/>
      </material>
    </visual>
    <collision>
      <geometry>
        <mesh filename="package://robot_description/meshes/ur3e/collision/wrist2.stl"/>
      </geometry>
    </collision>
    <inertial>
      <mass value="0.805"/>
      <origin rpy="0 0 0" xyz="0.0 0.0 0.0"/>
      <inertia ixx="0.0020980304107875002" ixy="0.0" ixz="0.0" iyy="0.0020980304107875002" iyz="0.0" izz="0.0022640625"/>
    </inertial>
  </link>
  <joint name="wrist_3_joint" type="revolute">
    <parent link="wrist_2_link"/>
    <child link="wrist_3_link"/>
    <origin rpy="0.0 0.0 0.0" xyz="0.0 0.0 0.08535"/>
    <axis xyz="0 1 0"/>
    <limit effort="12.0" lower="-3.141592653589793" upper="3.141592653589793" velocity="3.1415"/>
    <dynamics damping="0.0" friction="0.0"/>
  </joint>
  <link name="wrist_3_link">
    <visual>
      <geometry>
        <mesh filename="package://robot_description/meshes/ur3e/visual/wrist3.dae"/>
      </geometry>
      <material name="LightGrey">
        <color rgba="0.7 0.7 0.7 1.0"/>
      </material>
    </visual>
    <collision>
      <geometry>
        <mesh filename="package://robot_description/meshes/ur3e/collision/wrist3.stl"/>
      </geometry>
    </collision>
    <inertial>
      <mass value="0.805"/>
      <origin rpy="0 0 0" xyz="0.0 0.0 0.0"/>
      <inertia ixx="0.00031341320796800004" ixy="0.0" ixz="0.0" iyy="0.00031341320796800004" iyz="0.0" izz="0.00041216"/>
    </inertial>
  </link>
  <!--EndEffector Joint-->
  <joint name="ee_fixed_joint" type="fixed">
    <parent link="wrist_3_link"/>
    <child link="ee_link"/>
    <origin rpy="0.0 0.0 1.5707963267948966" xyz="0.0 0.0921 0.0"/>
  </joint>
  <!--EndEffector Link-->
  <link name="ee_link">
    <collision>
      <geometry>
        <box size="0.01 0.01 0.01"/>
      </geometry>
      <origin rpy="0 0 0" xyz="-0.01 0 0"/>
    </collision>
  </link>
  <!-- ROS base_link to UR 'Base' Coordinates transform -->
  <link name="base"/>
  <joint name="base_link-base_fixed_joint" type="fixed">
    <!-- NOTE: this rotation is only needed as long as base_link itself is
                 not corrected wrt the real robot (ie: rotated over 180  degrees)-->
    <origin rpy="0 0 -3.141592653589793" xyz="0 0 0"/>
    <parent link="base_link"/>
    <child link="base"/>
  </joint>
  <!-- Frame coincident with all-zeros TCP on UR controller -->
  <link name="tool0"/>
  <joint name="wrist_3_link-tool0_fixed_joint" type="fixed">
    <origin rpy="-1.5707963267948966 0 0" xyz="0 0.0921 0"/>
    <parent link="wrist_3_link"/>
    <child link="tool0"/>
  </joint>
  <link name="world"/>
  <joint name="world_joint" type="fixed">
    <parent link="world"/>
    <child link="base_link"/>
    <origin rpy="0.0 0.0 0.0" xyz="0.0 0.0 0.0"/>
  </joint>
  <!-- Schunk EGH80 Coupler -->
  <!--  -->
  <!--  -->
  <link name="conector_tcp">
    <visual>
      <origin rpy="0 -0 0" xyz="0 0 0"/>
      <geometry>
        <mesh filename="package://robot_description/meshes/conector_tcp.stl"/>
      </geometry>
      <material name="conector_tcp_material">
        <color rgba="0.50196078431372548323 0.50196078431372548323 0.50196078431372548323 1.0"/>
      </material>
    </visual>
    <collision>
      <origin rpy="0 -0 0" xyz="0 0 0"/>
      <geometry>
        <mesh filename="package://robot_description/meshes/conector_tcp.stl"/>
      </geometry>
    </collision>
    <inertial>
      <origin rpy="0 0 0" xyz="-3.517291045154929735e-05 -3.2279048367335561479e-13 0.0037918602136445983021"/>
      <mass value="0.17533775221511888054"/>
      <inertia ixx="4.7634466232920521231e-05" ixy="-1.9565925084430388539e-07" ixz="-1.9723444917313040303e-07" iyy="6.3135044798116074396e-05" iyz="1.9739250304519301961e-16" izz="0.00010757461602015991483"/>
    </inertial>
  </link>
  <joint name="conector_tcp_joint" type="fixed">
    <origin rpy="0.0 0.0 -1.5707963267948966" xyz="0.0 0.0 0.0"/>
    <parent link="tool0"/>
    <child link="conector_tcp"/>
  </joint>
  <gazebo reference="conector_tcp">
    <mu1>0.9</mu1>
    <mu2>0.9</mu2>
  </gazebo>
  <!-- Gripper-->
  <link name="schunk_egh80_link">
    <visual>
      <origin rpy="-1.3439035240356334011 -0 0" xyz="0.0 0.036423269171482079709 0.075503655548620457472"/>
      <geometry>
        <mesh filename="package://robot_description/meshes/schunk_egh80/visual/etiqueta.dae"/>
      </geometry>
      <material name="etiqueta_material">
        <color rgba="0.69019607843137253944 0.69019607843137253944 0.69019607843137253944 1.0"/>
      </material>
    </visual>
    <collision>
      <origin rpy="-1.3439035240356334011 -0 0" xyz="0.0 0.036423269171482079709 0.075503655548620457472"/>
      <geometry>
        <mesh filename="package://robot_description/meshes/schunk_egh80/collision/etiqueta.stl"/>
      </geometry>
    </collision>
    <visual>
      <origin rpy="0.0 -0 0" xyz="0.0 0.001000000000000025608 -0"/>
      <geometry>
        <mesh filename="package://robot_description/meshes/schunk_egh80/visual/egh_80.dae"/>
      </geometry>
      <material name="egh80_material">
        <color rgba="0.69019607843137253944 0.69019607843137253944 0.69019607843137253944 1.0"/>
      </material>
    </visual>
    <collision>
      <origin rpy="0.0 -0 0.0" xyz="0.0 0.001000000000000025608 -0"/>
      <geometry>
        <mesh filename="package://robot_description/meshes/schunk_egh80/collision/egh_80.stl"/>
      </geometry>
    </collision>
    <inertial>
      <origin rpy="0 0 0" xyz="0.0 0.00099144218198634042477 0.048851498325995605654"/>
      <mass value="0.8940741992945057115"/>
      <inertia ixx="0.00144341178416013214" ixy="-1.0815141178448789754e-07" ixz="-4.1196228146560501818e-07" iyy="0.0016329060271123971206" iyz="2.3017375574695289924e-07" izz="0.00088273402479363332826"/>
    </inertial>
  </link>
  <!--Right Finger-->
  <link name="dedo_dir">
    <visual>
      <origin rpy="3.141592653589793116 0 -3.141592653589793116" xyz="0.0023249999999999781258 0.08007769391666488823 0.031950000000000013112"/>
      <geometry>
        <mesh filename="package://robot_description/meshes/schunk_egh80/visual/almofada.dae"/>
      </geometry>
    </visual>
    <collision>
      <origin rpy="3.141592653589793116 0 -3.141592653589793116" xyz="0.0023249999999999781258 0.08007769391666488823 0.031950000000000013112"/>
      <geometry>
        <mesh filename="package://robot_description/meshes/schunk_egh80/collision/almofada.stl"/>
      </geometry>
    </collision>
    <visual>
      <origin rpy="-0 1.570796326794896558 0" xyz="0.0018250000000000375297 0.033299999999999774225 0.040700000000000007006"/>
      <geometry>
        <mesh filename="package://robot_description/meshes/schunk_egh80/visual/falanginha.dae"/>
      </geometry>
      <material name="falanginha_material">
        <color rgba="0.89803921568627453897 0.89803921568627453897 0.89803921568627453897 1.0"/>
      </material>
    </visual>
    <collision>
      <origin rpy="-0 1.570796326794896558 0" xyz="0.0018250000000000375297 0.033299999999999774225 0.040700000000000007006"/>
      <geometry>
        <mesh filename="package://robot_description/meshes/schunk_egh80/collision/falanginha.stl"/>
      </geometry>
    </collision>
    <visual>
      <origin rpy="-0 1.570796326794896336 0" xyz="0.0026249999999999433509 0.033299999999999801981 0.040700000000000007006"/>
      <geometry>
        <mesh filename="package://robot_description/meshes/schunk_egh80/visual/falange.dae"/>
      </geometry>
      <material name="falange_material">
        <color rgba="0.89803921568627453897 0.89803921568627453897 0.89803921568627453897 1.0"/>
      </material>
    </visual>
    <collision>
      <origin rpy="-0 1.570796326794896336 0" xyz="0.0026249999999999433509 0.033299999999999801981 0.040700000000000007006"/>
      <geometry>
        <mesh filename="package://robot_description/meshes/schunk_egh80/collision/falange.stl"/>
      </geometry>
    </collision>
    <visual>
      <origin rpy="-0 1.570796326794896558 0" xyz="0.0023249999999999772585 0.065299999999999774891 0.040700000000000007006"/>
      <geometry>
        <mesh filename="package://robot_description/meshes/schunk_egh80/visual/falangeta.dae"/>
      </geometry>
      <material name="falangeta_material">
        <color rgba="0.89803921568627453897 0.89803921568627453897 0.89803921568627453897 1.0"/>
      </material>
    </visual>
    <collision>
      <origin rpy="-0 1.570796326794896558 0" xyz="0.0023249999999999772585 0.065299999999999774891 0.040700000000000007006"/>
      <geometry>
        <mesh filename="package://robot_description/meshes/schunk_egh80/collision/falangeta.stl"/>
      </geometry>
    </collision>
    <visual>
      <origin rpy="-0 1.570796326794896558 0" xyz="0.0026250000000000014641 0.016000000000000014211 0.041500000000000009104"/>
      <geometry>
        <mesh filename="package://robot_description/meshes/schunk_egh80/visual/guia_dedo.dae"/>
      </geometry>
      <material name="guia_dedo_material">
        <color rgba="0.2313725490196078538 0.2313725490196078538 0.2313725490196078538 1.0"/>
      </material>
    </visual>
    <collision>
      <origin rpy="-0 1.570796326794896558 0" xyz="0.0026250000000000014641 0.016000000000000014211 0.041500000000000009104"/>
      <geometry>
        <mesh filename="package://robot_description/meshes/schunk_egh80/collision/guia_dedo.stl"/>
      </geometry>
    </collision>
    <inertial>
      <origin rpy="0 0 0" xyz="0.0029825365929367041173 0.0278015996536302816 0.03487164697684287662"/>
      <mass value="0.074377094721990874571"/>
      <inertia ixx="5.2720380310400654245e-05" ixy="1.3456724147132514789e-06" ixz="5.2493950544052393425e-07" iyy="1.0703934703923688915e-05" iyz="-7.363436738255669011e-06" izz="4.9495184444868198551e-05"/>
    </inertial>
  </link>
  <!-- Left Finger link-->
  <link name="dedo_esq">
    <visual>
      <origin rpy="3.141592653589793116 -0 -3.141592653589793116" xyz="0.0023249999999999668501 0.080077693916664902107 0.031949999999999985356"/>
      <geometry>
        <mesh filename="package://robot_description/meshes/schunk_egh80/visual/almofada.dae"/>
      </geometry>
    </visual>
    <collision>
      <origin rpy="3.141592653589793116 -0 -3.141592653589793116" xyz="0.0023249999999999668501 0.080077693916664902107 0.031949999999999985356"/>
      <geometry>
        <mesh filename="package://robot_description/meshes/schunk_egh80/collision/almofada.stl"/>
      </geometry>
    </collision>
    <visual>
      <origin rpy="0 1.570796326794896558 0" xyz="0.0018250000000000266877 0.033299999999999760347 0.040700000000000027822"/>
      <geometry>
        <mesh filename="package://robot_description/meshes/schunk_egh80/visual/falanginha.dae"/>
      </geometry>
    </visual>
    <collision>
      <origin rpy="0 1.570796326794896558 0" xyz="0.0018250000000000266877 0.033299999999999760347 0.040700000000000027822"/>
      <geometry>
        <mesh filename="package://robot_description/meshes/schunk_egh80/collision/falanginha.stl"/>
      </geometry>
    </collision>
    <visual>
      <origin rpy="0 1.570796326794896336 0" xyz="0.0026249999999999372793 0.033299999999999760347 0.040700000000000013944"/>
      <geometry>
        <mesh filename="package://robot_description/meshes/schunk_egh80/visual/falange.dae"/>
      </geometry>
    </visual>
    <collision>
      <origin rpy="0 1.570796326794896336 0" xyz="0.0026249999999999372793 0.033299999999999760347 0.040700000000000013944"/>
      <geometry>
        <mesh filename="package://robot_description/meshes/schunk_egh80/collision/falange.stl"/>
      </geometry>
    </collision>
    <visual>
      <origin rpy="0 1.570796326794896558 0" xyz="0.0023249999999999707533 0.065299999999999677747 0.040700000000000013944"/>
      <geometry>
        <mesh filename="package://robot_description/meshes/schunk_egh80/visual/falangeta.dae"/>
      </geometry>
    </visual>
    <collision>
      <origin rpy="0 1.570796326794896558 0" xyz="0.0023249999999999707533 0.065299999999999677747 0.040700000000000013944"/>
      <geometry>
        <mesh filename="package://robot_description/meshes/schunk_egh80/collision/falangeta.stl"/>
      </geometry>
    </collision>
    <visual>
      <origin rpy="0 1.570796326794896558 0" xyz="0.0026250000000000014641 0.016000000000000000333 0.041500000000000002165"/>
      <geometry>
        <mesh filename="package://robot_description/meshes/schunk_egh80/visual/guia_dedo.dae"/>
      </geometry>
    </visual>
    <collision>
      <origin rpy="0 1.570796326794896558 0" xyz="0.0026250000000000014641 0.016000000000000000333 0.041500000000000002165"/>
      <geometry>
        <mesh filename="package://robot_description/meshes/schunk_egh80/collision/guia_dedo.stl"/>
      </geometry>
    </collision>
    <inertial>
      <origin rpy="0 0 0" xyz="0.0029825365929366997805 0.027801599653630260783 0.03487164697684287662"/>
      <mass value="0.074377094721990874571"/>
      <inertia ixx="5.272038031040062714e-05" ixy="1.3456724147132578317e-06" ixz="5.2493950544052605183e-07" iyy="1.0703934703923699079e-05" iyz="-7.3634367382556766343e-06" izz="4.949518444486816467e-05"/>
    </inertial>
  </link>
  <joint name="gripper_base_joint" type="fixed">
    <origin rpy="0 0 1.570796326794896558" xyz="0 0 0"/>
    <parent link="tool0"/>
    <child link="schunk_egh80_link"/>
    <axis xyz="0 0 1"/>
    <!-- <limit effort="1" velocity="20" lower="0.0050000000000000001041" upper="0.044999999999999998335"/>
            <dynamics damping="0" friction="0"/> -->
  </joint>
  <!-- Juntas dos dedos -->
  <joint name="dedo_dir_joint" type="prismatic">
    <origin rpy="1.570796326794896558 0 -1.570796326794896558" xyz="0.032500000000000028866 0.0036249999999999928113 0.10919999999999996376"/>
    <axis xyz="0 0 1"/>
    <limit accelerarion="0.1" effort="1" lower="0.0" upper="0.040" velocity="0.08"/>
    <joint_properties friction="0.0"/>
    <parent link="schunk_egh80_link"/>
    <child link="dedo_dir"/>
    <mimic joint="dedo_esq_joint" multiplier="1"/>
  </joint>
  <joint name="dedo_esq_joint" type="prismatic">
    <origin rpy="1.570796326794896558 0 1.570796326794896558" xyz="-0.022499999999999978351 -0.0016250000000000075148 0.10919999999999994988"/>
    <axis xyz="0 0 1"/>
    <limit accelerarion="0.1" effort="1" lower="0.0" upper="0.040" velocity="0.08"/>
    <joint_properties friction="0.0"/>
    <parent link="schunk_egh80_link"/>
    <child link="dedo_esq"/>
  </joint>
  <ros2_control name="FakeSystem" type="system">
    <hardware>
      <!-- By default, set up controllers for simulation. This won't work on real hardware -->
      <plugin>topic_based_ros2_control/TopicBasedSystem</plugin>
      <param name="joint_commands_topic">/isaac_joint_commands</param>
      <param name="joint_state_topic">/isaac_joint_states</param>
    </hardware>
    <joint name="shoulder_pan_joint">
      <command_interface name="position"/>
      <state_interface name="position">
        <param name="initial_value">0</param>
      </state_interface>
      <state_interface name="velocity"/>
    </joint>
    <joint name="shoulder_lift_joint">
      <command_interface name="position"/>
      <state_interface name="position">
        <param name="initial_value">0</param>
      </state_interface>
      <state_interface name="velocity"/>
    </joint>
    <joint name="elbow_joint">
      <command_interface name="position"/>
      <state_interface name="position">
        <param name="initial_value">0</param>
      </state_interface>
      <state_interface name="velocity"/>
    </joint>
    <joint name="wrist_1_joint">
      <command_interface name="position"/>
      <state_interface name="position">
        <param name="initial_value">0</param>
      </state_interface>
      <state_interface name="velocity"/>
    </joint>
    <joint name="wrist_2_joint">
      <command_interface name="position"/>
      <state_interface name="position">
        <param name="initial_value">0</param>
      </state_interface>
      <state_interface name="velocity"/>
    </joint>
    <joint name="wrist_3_joint">
      <command_interface name="position"/>
      <state_interface name="position">
        <param name="initial_value">0</param>
      </state_interface>
      <state_interface name="velocity"/>
    </joint>
    <joint name="dedo_esq_joint">
      <command_interface name="position"/>
      <state_interface name="position">
        <param name="initial_value">0</param>
      </state_interface>
      <state_interface name="velocity"/>
    </joint>
  </ros2_control>
</robot>
